Overriding model.yaml nc=80 with nc=10
                 from  n    params  module                                  arguments
  0                -1  1      3520  models.common.Conv                      [3, 32, 6, 2, 2]
  1                -1  1     18560  models.common.Conv                      [32, 64, 3, 2]
  2                -1  1     18816  models.common.C3                        [64, 64, 1]
  3                -1  1     73984  models.common.Conv                      [64, 128, 3, 2]
  4                -1  2    115712  models.common.C3                        [128, 128, 2]
  5                -1  1    295424  models.common.Conv                      [128, 256, 3, 2]
  6                -1  3    625152  models.common.C3                        [256, 256, 3]
  7                -1  1   1180672  models.common.Conv                      [256, 512, 3, 2]
  8                -1  1   1182720  models.common.C3                        [512, 512, 1]
  9                -1  1    656896  models.common.SPPF                      [512, 512, 5]
 10                -1  1    131584  models.common.Conv                      [512, 256, 1, 1]
 11                -1  1         0  torch.nn.modules.upsampling.Upsample    [None, 2, 'nearest']
 12           [-1, 6]  1         0  models.common.Concat                    [1]
 13                -1  1    361984  models.common.C3                        [512, 256, 1, False]
 14                -1  1     33024  models.common.Conv                      [256, 128, 1, 1]
 15                -1  1         0  torch.nn.modules.upsampling.Upsample    [None, 2, 'nearest']
 16           [-1, 4]  1         0  models.common.Concat                    [1]
 17                -1  1     90880  models.common.C3                        [256, 128, 1, False]
 18                -1  1    147712  models.common.Conv                      [128, 128, 3, 2]
 19          [-1, 14]  1         0  models.common.Concat                    [1]
 20                -1  1    296448  models.common.C3                        [256, 256, 1, False]
 21                -1  1    590336  models.common.Conv                      [256, 256, 3, 2]
 22          [-1, 10]  1         0  models.common.Concat                    [1]
 23                -1  1   1182720  models.common.C3                        [512, 512, 1, False]
 24      [17, 20, 23]  1     40455  models.yolo.Detect                      [10, [[10, 13, 16, 30, 33, 23], [30, 61, 62, 45, 59, 119], [116, 90, 156, 198, 373, 326]], [128, 256, 512]]
Model Summary: 270 layers, 7046599 parameters, 7046599 gradients
Transferred 343/349 items from yolov5s.pt
Scaled weight_decay = 0.0005
[34m[1moptimizer:[39m[22m SGD with parameter groups 57 weight, 60 weight (no decay), 60 bias
[34m[1malbumentations: [39m[22mBlur(always_apply=False, p=0.01, blur_limit=(3, 7)), MedianBlur(always_apply=False, p=0.01, blur_limit=(3, 7)), ToGray(always_apply=False, p=0.01), CLAHE(always_apply=False, p=0.01, clip_limit=(1, 4.0), tile_grid_size=(8, 8))
[34m[1mtrain: [39m[22mScanning '/opt/ml/detection/yolov5/dataset/labels/train.cache' images and labels... 4883 found, 0 missing, 0 empty, 1 corrupted: 100%|â–ˆâ–ˆâ–ˆâ–ˆâ–ˆâ–ˆâ–ˆâ–ˆâ–ˆâ–ˆâ–ˆâ–ˆâ–ˆâ–ˆâ–ˆâ–ˆâ–ˆâ–ˆâ–ˆâ–ˆâ–ˆâ–ˆâ–ˆâ–ˆâ–ˆâ–ˆ| 4883/4883 [00:00<?, ?it/s]
[34m[1mtrain: [39m[22mWARNING: Ignoring corrupted image and/or label /opt/ml/detection/yolov5/dataset/images/train/4041.jpg: duplicate labels
[34m[1mval: [39m[22mScanning '/opt/ml/detection/yolov5/dataset/labels/train.cache' images and labels... 4883 found, 0 missing, 0 empty, 1 corrupted: 100%|â–ˆâ–ˆâ–ˆâ–ˆâ–ˆâ–ˆâ–ˆâ–ˆâ–ˆâ–ˆâ–ˆâ–ˆâ–ˆâ–ˆâ–ˆâ–ˆâ–ˆâ–ˆâ–ˆâ–ˆâ–ˆâ–ˆâ–ˆâ–ˆâ–ˆâ–ˆâ–ˆâ–ˆ| 4883/4883 [00:00<?, ?it/s]
[34m[1mtrain: [39m[22mWARNING: Ignoring corrupted image and/or label /opt/ml/detection/yolov5/dataset/images/train/4041.jpg: duplicate labels
Plotting labels...
ERROR: Unexpected bus error encountered in worker. This might be caused by insufficient shared memory (shm).
ERROR: Unexpected bus error encountered in worker. This might be caused by insufficient shared memory (shm).
ERROR: Unexpected bus error encountered in worker. This might be caused by insufficient shared memory (shm).
ERROR: Unexpected bus error encountered in worker. This might be caused by insufficient shared memory (shm).
ERROR: Unexpected bus error encountered in worker. This might be caused by insufficient shared memory (shm).
ERROR: Unexpected bus error encountered in worker. This might be caused by insufficient shared memory (shm).
Error in sys.excepthook:
Traceback (most recent call last):
  File "/opt/conda/envs/detection/lib/python3.7/linecache.py", line 47, in getlines
    return updatecache(filename, module_globals)
  File "/opt/conda/envs/detection/lib/python3.7/linecache.py", line 137, in updatecache
    lines = fp.readlines()
  File "/opt/conda/envs/detection/lib/python3.7/codecs.py", line 319, in decode
    def decode(self, input, final=False):
  File "/opt/conda/envs/detection/lib/python3.7/site-packages/torch/utils/data/_utils/signal_handling.py", line 66, in handler
    _error_if_any_worker_fails()
RuntimeError: DataLoader worker (pid 119940) is killed by signal: Bus error. It is possible that dataloader's workers are out of shared memory. Please try to raise your shared memory limit.
Original exception was:
Traceback (most recent call last):
  File "train.py", line 620, in <module>
    main(opt)
  File "train.py", line 517, in main
    train(opt.hyp, opt, device, callbacks)
  File "train.py", line 231, in train
    plot_labels(labels, names, save_dir)
  File "/opt/ml/detection/yolov5/utils/plots.py", line 335, in plot_labels
    plt.savefig(save_dir / 'labels.jpg', dpi=200)
  File "/opt/conda/envs/detection/lib/python3.7/site-packages/matplotlib/pyplot.py", line 966, in savefig
    res = fig.savefig(*args, **kwargs)
  File "/opt/conda/envs/detection/lib/python3.7/site-packages/matplotlib/figure.py", line 3015, in savefig
    self.canvas.print_figure(fname, **kwargs)
  File "/opt/conda/envs/detection/lib/python3.7/site-packages/matplotlib/backend_bases.py", line 2261, in print_figure
    **kwargs)
  File "/opt/conda/envs/detection/lib/python3.7/site-packages/matplotlib/backend_bases.py", line 1669, in wrapper
    return func(*args, **kwargs)
  File "/opt/conda/envs/detection/lib/python3.7/site-packages/matplotlib/_api/deprecation.py", line 431, in wrapper
Exception in thread Thread-14:
Traceback (most recent call last):
  File "/opt/conda/envs/detection/lib/python3.7/threading.py", line 926, in _bootstrap_inner
    self.run()
  File "/opt/conda/envs/detection/lib/python3.7/threading.py", line 870, in run
    self._target(*self._args, **self._kwargs)
  File "/opt/conda/envs/detection/lib/python3.7/site-packages/torch/utils/data/_utils/pin_memory.py", line 25, in _pin_memory_loop
    r = in_queue.get(timeout=MP_STATUS_CHECK_INTERVAL)
  File "/opt/conda/envs/detection/lib/python3.7/multiprocessing/queues.py", line 113, in get
    return _ForkingPickler.loads(res)
  File "/opt/conda/envs/detection/lib/python3.7/site-packages/torch/multiprocessing/reductions.py", line 282, in rebuild_storage_fd
    fd = df.detach()
  File "/opt/conda/envs/detection/lib/python3.7/multiprocessing/resource_sharer.py", line 57, in detach
    with _resource_sharer.get_connection(self._id) as conn:
  File "/opt/conda/envs/detection/lib/python3.7/multiprocessing/resource_sharer.py", line 87, in get_connection
    c = Client(address, authkey=process.current_process().authkey)
  File "/opt/conda/envs/detection/lib/python3.7/multiprocessing/connection.py", line 498, in Client
    answer_challenge(c, authkey)
  File "/opt/conda/envs/detection/lib/python3.7/multiprocessing/connection.py", line 742, in answer_challenge
    message = connection.recv_bytes(256)         # reject large message
  File "/opt/conda/envs/detection/lib/python3.7/multiprocessing/connection.py", line 216, in recv_bytes
    buf = self._recv_bytes(maxlength)
  File "/opt/conda/envs/detection/lib/python3.7/multiprocessing/connection.py", line 407, in _recv_bytes
    buf = self._recv(4)
  File "/opt/conda/envs/detection/lib/python3.7/multiprocessing/connection.py", line 379, in _recv
    chunk = read(handle, remaining)
ConnectionResetError: [Errno 104] Connection reset by peer
    return func(*inner_args, **inner_kwargs)
  File "/opt/conda/envs/detection/lib/python3.7/site-packages/matplotlib/_api/deprecation.py", line 431, in wrapper
    return func(*inner_args, **inner_kwargs)
  File "/opt/conda/envs/detection/lib/python3.7/site-packages/matplotlib/_api/deprecation.py", line 431, in wrapper
    return func(*inner_args, **inner_kwargs)
  File "/opt/conda/envs/detection/lib/python3.7/site-packages/matplotlib/backends/backend_agg.py", line 564, in print_jpg
    FigureCanvasAgg.draw(self)
  File "/opt/conda/envs/detection/lib/python3.7/site-packages/matplotlib/backends/backend_agg.py", line 406, in draw
    self.figure.draw(self.renderer)
  File "/opt/conda/envs/detection/lib/python3.7/site-packages/matplotlib/artist.py", line 74, in draw_wrapper
    result = draw(artist, renderer, *args, **kwargs)
  File "/opt/conda/envs/detection/lib/python3.7/site-packages/matplotlib/artist.py", line 51, in draw_wrapper
    return draw(artist, renderer, *args, **kwargs)
  File "/opt/conda/envs/detection/lib/python3.7/site-packages/matplotlib/figure.py", line 2791, in draw
    renderer, self, artists, self.suppressComposite)
  File "/opt/conda/envs/detection/lib/python3.7/site-packages/matplotlib/image.py", line 132, in _draw_list_compositing_images
    a.draw(renderer)
  File "/opt/conda/envs/detection/lib/python3.7/site-packages/matplotlib/artist.py", line 51, in draw_wrapper
    return draw(artist, renderer, *args, **kwargs)
  File "/opt/conda/envs/detection/lib/python3.7/site-packages/matplotlib/_api/deprecation.py", line 431, in wrapper
    return func(*inner_args, **inner_kwargs)
  File "/opt/conda/envs/detection/lib/python3.7/site-packages/matplotlib/axes/_base.py", line 2921, in draw
    mimage._draw_list_compositing_images(renderer, self, artists)
  File "/opt/conda/envs/detection/lib/python3.7/site-packages/matplotlib/image.py", line 132, in _draw_list_compositing_images
    a.draw(renderer)
  File "/opt/conda/envs/detection/lib/python3.7/site-packages/matplotlib/artist.py", line 51, in draw_wrapper
    return draw(artist, renderer, *args, **kwargs)
  File "/opt/conda/envs/detection/lib/python3.7/site-packages/matplotlib/image.py", line 641, in draw
    renderer, renderer.get_image_magnification())
  File "/opt/conda/envs/detection/lib/python3.7/site-packages/matplotlib/image.py", line 927, in make_image
    magnification, unsampled=unsampled)
  File "/opt/conda/envs/detection/lib/python3.7/site-packages/matplotlib/image.py", line 552, in _make_image
    self, _rgb_to_rgba(A[..., :3]), out_shape, t, alpha=alpha)
  File "/opt/conda/envs/detection/lib/python3.7/site-packages/matplotlib/image.py", line 208, in _rgb_to_rgba
    rgba[:, :, :3] = A
  File "/opt/conda/envs/detection/lib/python3.7/site-packages/torch/utils/data/_utils/signal_handling.py", line 66, in handler
    _error_if_any_worker_fails()
RuntimeError: DataLoader worker (pid 119952) is killed by signal: Bus error. It is possible that dataloader's workers are out of shared memory. Please try to raise your shared memory limit.